Traceback (most recent call last):
  File "<frozen importlib._bootstrap_external>", line 148, in _path_is_mode_type
  File "<frozen importlib._bootstrap_external>", line 142, in _path_stat
FileNotFoundError: [Errno 2] No such file or directory: '/usr/lib/python3/dist-packages/zope/__init__.abi3.so'

During handling of the above exception, another exception occurred:

Traceback (most recent call last):
  File "setup.py", line 3, in <module>
    from setuptools import setup
  File "/usr/lib/python3/dist-packages/setuptools/__init__.py", line 17, in <module>
    import setuptools.version
  File "/usr/lib/python3/dist-packages/setuptools/version.py", line 1, in <module>
    import pkg_resources
  File "/usr/lib/python3/dist-packages/pkg_resources/__init__.py", line 3254, in <module>
    def _initialize_master_working_set():
  File "/usr/lib/python3/dist-packages/pkg_resources/__init__.py", line 3237, in _call_aside
    f(*args, **kwargs)
  File "/usr/lib/python3/dist-packages/pkg_resources/__init__.py", line 3279, in _initialize_master_working_set
    tuple(
  File "/usr/lib/python3/dist-packages/pkg_resources/__init__.py", line 3280, in <genexpr>
    dist.activate(replace=False)
  File "/usr/lib/python3/dist-packages/pkg_resources/__init__.py", line 2784, in activate
    fixup_namespace_packages(self.location)
  File "/usr/lib/python3/dist-packages/pkg_resources/__init__.py", line 2296, in fixup_namespace_packages
    subpath = _handle_ns(package, path_item)
  File "/usr/lib/python3/dist-packages/pkg_resources/__init__.py", line 2202, in _handle_ns
    loader = importer.find_module(packageName)
  File "<frozen importlib._bootstrap_external>", line 546, in _find_module_shim
  File "<frozen importlib._bootstrap_external>", line 1488, in find_loader
  File "<frozen importlib._bootstrap_external>", line 1525, in find_spec
  File "<frozen importlib._bootstrap_external>", line 156, in _path_isfile
  File "<frozen importlib._bootstrap_external>", line 148, in _path_is_mode_type
KeyboardInterrupt
